Workbook

Sheet Câu hỏi vòng 2
A1: CÂU HỎI LÀM RÕ VÒNG 2 — INVOICE ISSUANCE ARCHITECTURE v2.0 (URD rev 2.2)
A2: Sau khi QC trả lời vòng 1 (20/49 câu) và đối chiếu flow URD §B.I–III, ngày 16/10/2026. Chỉ gồm câu còn Open; câu đã chốt xem sheet "Đã chốt vòng 1". Câu "Rõ một phần" đã được viết lại, chỉ hỏi phần còn thiếu. Nguồn: 02_analyze-requirements/v2.0/<MODULE>/risk_assessment.md. Cột vàng để PO / BA điền.
A4: STT | B4: Mã câu hỏi | C4: Module | D4: Nội dung cần làm rõ | E4: Câu hỏi cho PO / BA (vòng 2) | F4: Mức độ | G4: Mã GAP (DOC-READINESS) | H4: Tình trạng sau vòng 1 | I4: Trả lời vòng 1 (QC) | J4: Đã cập nhật vào analyze | K4: Vị trí trong tài liệu | L4: Trích dẫn tài liệu (nguyên văn) | M4: Phân tích của QC | N4: REQ liên quan | O4: SC phụ thuộc trực tiếp | P4: Trạng thái | Q4: Câu trả lời của QC | R4: Người trả lời | S4: Ngày trả lời
A5: 1 | B5: CL-XHD-01 | C5: XHD | D5: BR-DB-01 chỉ còn 2 sự kiện, nhưng BR khác vẫn cần "tạo đơn" và "cập nhật thông tin khách" | E5: Trước khi phát hành HĐ, SPF có gửi sang INVOICE (a) bản tin khi đơn được tạo và (b) bản tin khi KH sửa thông tin (tên, MST, địa chỉ xuất HĐ…) không? Nếu không có (a): "thời gian tạo đơn" dùng cho delay 2h FPL (BR-XHD-03) lấy từ trường nào của bản tin thanh toán? Nếu không có (b): "thông tin mới nhất" của BR-DB-03 lấy từ đâu tại thời điểm phát hành? | F5: Critical | G5: GAP-42 | H5: QC đã rà — chuyển PO | I5: Cần làm rõ là đồng bộ thông tin gì, lúc nào, nếu sau khi phát hành sẽ không cập nhật thông tin khách hàng/ đơn hàng, nếu đồng bộ trước khi phát hàng hóa đơn thì sẽ hỏi lại đồng bộ sự kiện "tạo đơn" và "cập nhật thông tin khách hàng" | J5: 🔎 QC rà lại 16/10/2026: QC đề nghị hỏi rõ hơn: SPF đồng bộ thông tin gì, vào lúc nào. Sau khi phát hành thì HĐ không cập nhật lại thông tin KH / đơn; nếu có đồng bộ trước khi phát hành thì đó chính là 2 sự kiện "tạo đơn" / "cập nhật thông tin KH". Flow §B.I.b (DOC-v2.0-FIG-03 (ảnh: Workflow ĐỒNG BỘ & XUẤT HÓA ĐƠN TỰ ĐỘNG (v2.0).png)) bước 1 chỉ ghi "Nhận đơn hàng và tín hiệu giao · BR-DB-01, 02" — không bổ sung sự kiện. ⇒ Vẫn Open. Nguồn: QC trả lời 16/10/2026 vòng 1 | K5: DOC-v2.0-01 BR-DB-01 (L345) ↔ BR-DB-03 (L359) ↔ BR-XHD-03 (L399) | L5: [BR-DB-01 — DOC-v2.0-01 §I.c · L345] Áp dụng chung cho mọi kênh bán: thanh toán, hủy đơn hàng. [BR-DB-03 — dùng sự kiện không còn trong danh sách — L359] Cập nhật thông tin khách không kích hoạt phát hành hóa đơn; lần phát hành tiếp theo dùng thông tin mới nhất. [BR-XHD-03 — mốc cần dữ liệu tạo đơn — L399] Kênh bán FPL: Xét delay 2h (lấy chuẩn theo thời gian tạo đơn) | M5: Doc tự mâu thuẫn. SC-XHD-020 giữ chỗ, Then chờ câu trả lời. | N5: REQ-XHD-003, REQ-XHD-008 | O5: SC-XHD-020 | P5: Open
A6: 2 | B6: CL-XHD-02 | C6: XHD | D6: FPL: khách không lấy HĐ, hoặc quá 2 giờ không nhập thì sao? "(ví dụ FPL)" có kênh khác không? | E6: Trên kênh FPL, khách chọn lấy / không lấy HĐ và nhập thông tin ở bước nào (lúc đặt đơn hay sau khi đặt), INVOICE nhận lựa chọn này qua trường nào? Với 2 tình huống: (1) khách chọn không lấy HĐ — INVOICE vẫn phát hành HĐ với thông tin hợp đồng, hay không phát hành? (2) khách chọn lấy HĐ nhưng hết 2 giờ vẫn chưa nhập — phát hành với thông tin hợp đồng, hay không phát hành? | F6: Critical | G6: GAP-48 | H6: Rõ một phần | I6: Làm rõ thao tác như thế nào? Ngoại lệ chỉ áp FPL (10) Chỉnh lại câu hỏi rõ hơn giúp mình nha | J6: 🟡 Làm rõ một phần 16/10/2026 — Đã chốt (3): ngoại lệ chọn lấy / không lấy HĐ chỉ áp kênh FPL (10); flow DOC-v2.0-FIG-03 (ảnh: Workflow ĐỒNG BỘ & XUẤT HÓA ĐƠN TỰ ĐỘNG (v2.0).png) ghi "Kênh FPL: khách chọn lấy hóa đơn thì tự nhập thông tin trong tối đa 2 giờ" (không còn chữ "ví dụ"). Còn mở (1), (2); QC đề nghị hỏi rõ thao tác. Nguồn: QC trả lời 16/10/2026 vòng 1 | K6: DOC-v2.0-01 BR-DB-03 · L356-358 | L6: Ngoại lệ: kênh bán FPL cho khách chọn có lấy hóa đơn hay không (ví dụ FPL). (...) Khách được nhập thông tin trong tối đa 2 giờ, tính từ thời điểm ghi nhận trên hệ thống của kênh. | M6: 2 nhánh không có đầu ra. Theo quy định HĐĐT vẫn phải lập HĐ dù khách không lấy — suy diễn của analyst, cần xác nhận. Ảnh hưởng SC-XHD-032..034. | N6: REQ-XHD-007 | O6: SC-XHD-032, SC-XHD-033, SC-XHD-034 | P6: Open
A7: 3 | B7: CL-XHD-03 | C7: XHD | D7: 7 trường khách FPL tự nhập: bắt buộc, định dạng, ai kiểm tra? | E7: Xác nhận kênh FPL kiểm tra dữ liệu khách nhập và INVOICE không kiểm lại? Nếu đúng, cho QC quy tắc kiểm tra của kênh FPL (trường bắt buộc, định dạng MST / email / SĐT) và nhờ đội dự án FPL hướng dẫn thao tác nhập trên STG. | F7: Major | G7: GAP-49 | H7: QC đã rà — chuyển PO | I7: theo logic FPL phải tự kiếm trả nhưng phải chờ đội dự án hướng đã thao tác lúc đó mới đưa ra quyết định được | J7: 🔎 QC rà lại 16/10/2026: Theo logic, kênh FPL phải tự kiểm tra dữ liệu khách nhập; cần đội dự án hướng dẫn thao tác thực tế rồi mới chốt. ⇒ Vẫn Open. Nguồn: QC trả lời 16/10/2026 vòng 1 | K7: DOC-v2.0-01 BR-DB-03 · L357 | L7: Nếu khách chọn lấy hóa đơn thì dùng thông tin khách tự nhập: tên, email, số điện thoại, mã số thuế, mã định danh, mã quan hệ ngân sách, số hộ chiếu. | M7: Không có rule validate ⇒ test_data_catalog.md chỉ ghi được "có / rỗng". Nếu kênh FPL tự kiểm thì INVOICE chỉ nhận dữ liệu đã sạch. | N7: REQ-XHD-007 | O7: — | P7: Open
A8: 4 | B8: CL-XHD-04 | C8: XHD | D8: Mốc delay 2h của FPL: "thời gian tạo đơn" hay "thời điểm ghi nhận trên hệ thống của kênh"? Áp cho DV hay cả TB? | E8: (1) Delay 2h xét xuất HĐ kênh FPL áp cho dòng DV, dòng TB hay cả hai? (2) "Thời điểm ghi nhận trên hệ thống của kênh" (mốc bắt đầu 2 giờ nhập thông tin) có trùng "thời gian tạo đơn" (mốc delay 2h) không? Nếu khác nhau, HĐ có thể phát hành khi khách vẫn còn thời gian nhập — khi đó dùng thông tin nào? | F8: Major | G8: GAP-51 | H8: Rõ một phần | I8: BR-DB-03 — L358] Khách được nhập thông tin trong tối đa 2 giờ chỗ này là thời gian đồng bộ data còn - Thời gian khác hàng nhập [BR-XHD-03 — L399] Kênh bán FPL: Xét delay 2h (lấy chuẩn theo thời gian tạo đơn ) chỗ này là thời gian để xuất hóa đơn | J8: 🟡 Làm rõ một phần 16/10/2026 — Đã chốt: hai mốc 2 giờ là hai việc khác nhau. BR-DB-03 (L358) = thời hạn khách nhập thông tin, tính từ thời điểm ghi nhận trên hệ thống của kênh. BR-XHD-03 (L399) = delay xét xuất HĐ, tính từ thời gian tạo đơn. Còn mở: delay áp DV, TB hay cả hai; và nếu 2 mốc gốc lệch nhau thì HĐ có thể ra trước khi khách hết hạn nhập. Nguồn: QC trả lời 16/10/2026 vòng 1 | K8: DOC-v2.0-01 BR-XHD-03 (L399) ↔ BR-DB-03 (L358) | L8: [BR-XHD-03 — L399] Kênh bán FPL: Xét delay 2h (lấy chuẩn theo thời gian tạo đơn) [BR-DB-03 — L358] Khách được nhập thông tin trong tối đa 2 giờ, tính từ thời điểm ghi nhận trên hệ thống của kênh. | M8: Hai mốc 2 giờ dùng 2 cách gọi khác nhau; nếu khác thời điểm thì có thể phát hành trước khi khách hết hạn nhập. | N8: REQ-XHD-021 | O8: SC-XHD-050 | P8: Open
A9: 5 | B9: CL-XHD-05 | C9: XHD | D9: Lịch FPL "2h quét 1 lần": các mốc chạy và giờ chốt cụ thể? Có là tham số? | E9: BR-XHD-01 cho biết FPL quét 2 giờ/lần và đợt 22:05 chốt từ 0h–22h. Cần thêm: (1) các đợt trước 22:05 chạy lúc mấy giờ (vd 00:05, 02:05 … 20:05?) và mỗi đợt chốt dữ liệu tới giờ nào; (2) "hai khung giờ trước" trong câu L388 là 2 đợt nào; (3) ngoài phạm vi quét 0h–22h, đợt 22:05 còn khác các đợt 2 giờ thường ở điểm nào? | F9: Critical | G9: GAP-50, GAP-52 | H9: Rõ một phần | I9: Check BR-XHD-01 giúp mình nha | J9: 🟡 Làm rõ một phần 16/10/2026 — QC nhờ rà lại BR-XHD-01. URD đã nói được: BR-XHD-01 — tiêu đề + phạm vi lịch chung — L379-380 Lịch xuất hóa đơn (tham số cấu hình) Dùng chung một lịch cho mọi ngày và mọi kênh bán khác FPL BR-XHD-06 — FPL — L414 Đối với Kênh bán FPL chỉ realtime từ sau mốc 22h Flow §B.I.b — DOC-v2.0-FIG-03 (ảnh: Workflow ĐỒNG BỘ & XUẤT HÓA ĐƠN TỰ ĐỘNG (v2.0).png) (ghi chú bước "Luồng worker / realtime") Giờ chốt, giờ chạy là tham số cấu hình (BR-XHD-01, 02, 06). ⇒ Đã rõ: FPL quét 2 giờ/lần; đợt cuối 22:05 chốt từ 0h–22h; sau 22h FPL chỉ realtime; giờ chốt / giờ chạy là tham số cấu hình. "Không chia theo kênh" ở §A.1 được L380 giới hạn lại ("kênh bán khác FPL") ⇒ GAP-52 không còn mâu thuẫn. Còn mở: giờ chạy các đợt trước 22:05, mỗi đợt chốt tới giờ nào, "hai khung giờ trước" là khung nào. Nguồn: QC trả lời 16/10/2026 vòng 1 | K9: DOC-v2.0-01 BR-XHD-01 · L386-388 ↔ §A.1 #3 · L63 | L9: Xét riêng cho kênh bán FPL: 2h quét 1 lần Mốc 22:05 chốt từ 0h đến 22 giờ (Do FPL có rule delay 2h nên phải bổ sung khung giờ để quét hết những case không quét được do delay ở hai khung giờ trước) [§A.1 #3 — mục tiêu nói lịch chung — L63] Xuất hóa đơn cho tất cả kênh bán liệt kê bên đưới và có đơn hàng SPF, dùng một lịch chung (giờ chốt và giờ chạy là tham số cấu hình) thay vì chia theo kênh và theo ngày thường / cuối tháng. | M9: Không biết đợt đầu chạy lúc mấy giờ, mỗi đợt chốt tới đâu, "hai khung giờ trước" là khung nào. Mục tiêu §A.1 "không chia theo kênh" mâu thuẫn với lịch riêng FPL (GAP-52). | N9: REQ-XHD-017, REQ-XHD-026 | O9: SC-XHD-047 | P9: Open
A10: 6 | B10: CL-XHD-07 | C10: XHD | D10: PĐK: nhận diện HĐ tổ chức, nguồn trạng thái PĐK, cách tính "2 ngày cuối tháng", duyệt muộn | E10: (1) HĐ tổ chức bị chặn vì chưa duyệt PĐK, sau đó PĐK được duyệt: đợt worker sau có phát hành không, hay "không autobill" nghĩa là phải xuất tay? (2) Đơn bán thêm trên HĐ tổ chức: xét PĐK của hợp đồng (đã duyệt từ lần bán mới) hay cần PĐK mới cho đơn bán thêm? (3) Trạng thái PĐK nằm ở trường nào trong dữ liệu SPF gửi sang? | F10: Critical | G10: GAP-44, GAP-45, GAP-61 | H10: Rõ một phần | I10: HĐ có loại hình KH cấp 1 = Tổ chức, trạng thái PĐK lấy từ SPF, "2 ngày cuối tháng" = 2 ngày lịch , | J10: 🟡 Làm rõ một phần 16/10/2026 — Đã chốt: (1) HĐ tổ chức = hợp đồng có loại hình KH cấp 1 = Tổ chức; (2) trạng thái PĐK lấy từ SPF; (3) "2 ngày cuối tháng" = 2 ngày lịch cuối cùng của tháng. Còn mở: (4) duyệt PĐK muộn; PĐK của đơn bán thêm (GAP-61); trường SPF trả trạng thái PĐK. Nguồn: QC trả lời 16/10/2026 vòng 1 | K10: DOC-v2.0-01 BR-XHD-03 · L400 | L10: Hợp đồng tổ chức: chỉ phát hành khi đã duyệt PĐK; hai ngày cuối tháng không xét điều kiện này. Quên duyệt PĐK thì không autobill. Khi có thay đổi hoặc dịch chuyển luồng duyệt PĐK/hợp đồng thì phải hiệu chỉnh lại điều kiện này. | M10: 4 điểm mở: (1) trường nào đánh dấu HĐ tổ chức (loại hình KH cấp 1?); (2) trạng thái PĐK lấy từ hệ thống nào; (3) "2 ngày cuối tháng" = 2 ngày lịch hay 2 ngày làm việc; (4) PĐK duyệt sau khi bị chặn thì đợt sau có phát hành. Thêm đơn bán thêm trên HĐ tổ chức đã duyệt PĐK: xét PĐK của lần nào (GAP-61). Ảnh hưởng SC-XHD-061..065, 068. | N10: REQ-XHD-022 | O10: SC-XHD-064, SC-XHD-065 | P10: Open
A11: 7 | B11: CL-XHD-08 | C11: XHD | D11: Hợp đồng con không phát hành: ghi nhận ra sao? HĐ cha có phát hành thay? | E11: Dòng DV / TB trên hợp đồng con bị chặn thì hệ thống ghi nhận thế nào (ghi log ở đâu, đánh cờ, hay để tồn)? Phần này có được xuất trên HĐ của hợp đồng cha (dự án) không, hay xuất theo quy trình khác? | F11: Major | G11: GAP-46 | H11: Rõ một phần | I11: Vào tool tình trạng check xem có thông tin hd cha không nến có thì HD đó là HD còn | J11: 🟡 Làm rõ một phần 16/10/2026 — Đã chốt cách nhận diện khi chuẩn bị dữ liệu: vào tool tình trạng kiểm tra hợp đồng; có thông tin hợp đồng cha ⇒ là hợp đồng con. Còn mở: dòng bị chặn được ghi nhận thế nào, HĐ cha có xuất thay không. Nguồn: QC trả lời 16/10/2026 vòng 1 | K11: DOC-v2.0-01 BR-XHD-03 · L401 | L11: Hợp đồng con: nhận diện hợp đồng con khi hợp đồng có gắn hợp đồng cha (hợp đồng dự án). Không phát hành hóa đơn trên hợp đồng con, cả thiết bị và dịch vụ. | M11: SC-XHD-066, 067 chỉ kiểm được "không phát hành". Không rõ có log, có cờ, hay dòng nằm tồn mãi. | N11: REQ-XHD-023 | O11: — | P11: Open
A12: 8 | B12: CL-XHD-11 | C12: XHD | D12: Khóa chống trùng chốt theo bản nào, gồm field nào? | E12: "Dịch vụ hóa đơn" và "Gói dịch vụ" trong khóa chống trùng BR-XHD-08 ứng với cột nào trong dữ liệu đơn (bảng chi tiết đơn: ServiceCode? mã gói? SubServiceType?) | F12: Critical | G12: GAP-41, GAP-56 | H12: Rõ một phần | I12: theo FILE V2.2 | J12: 🟡 Làm rõ một phần 16/10/2026 — Đã chốt theo URD 2.2 (L419): DV = mã đơn hàng + dịch vụ hóa đơn + gói dịch vụ; TB thêm phương thức triển khai. Câu §C#3 L651 ("khóa chống trùng có dùng SubServiceType") hết hiệu lực với chống trùng. Khóa map tín hiệu BR-DB-07 L374 (có SubserviceType) là khóa khác, giữ nguyên. Còn mở: field dữ liệu của "dịch vụ hóa đơn" và "gói dịch vụ" — cần schema (CL-XHD-29). Hết BLOCKING: SC-XHD-076..078 viết được TC theo khóa 2.2, chỉ phần field cụ thể của dữ liệu test chờ schema. Nguồn: QC trả lời 16/10/2026 vòng 1 | K12: DOC-v2.0-01 BR-XHD-08 (L419) ↔ §C#3 (L649-651) ↔ BR-DB-07 (L374) | L12: [URD 2.2 BR-XHD-08 — L419, L422] Khóa xác định dòng: dịch vụ = mã đơn hàng + dịch vụ hóa đơn + Gói dịch vụ; thiết bị thêm phương thức triển khai. (...) Giữ nguyên [URD 2.2 §C#3 — vẫn nói khóa dùng SubServiceType — L651] Khóa chống trùng có dùng SubServiceType nên có thể làm hai dòng bị coi là trùng. | M12: 2.2 đổi khóa nhưng ghi "Giữ nguyên"; §C#3 và BR-DB-07 vẫn theo khóa cũ. "Dịch vụ hóa đơn" và "Gói dịch vụ" ứng với field nào trong dữ liệu chưa rõ. Theo quy tắc 2.2 thắng, TP giả định theo text 2.2. ⛔ Không sinh TC chi tiết dữ liệu khóa cho SC-XHD-076..079 tới khi trả lời. | N12: REQ-XHD-012, REQ-XHD-027 | O12: SC-XHD-079 | P12: Open
A13: 9 | B13: CL-XHD-12 | C13: XHD | D13: SubServiceType 31 trùng ở 2 dịch vụ Tổng đài Oncall | E13: SubServiceType của "Thiết bị IP phone" đúng là 31 (trùng "Thiết bị Oncall") không? Nếu đúng, tín hiệu giao hàng map theo mã đơn + ServiceCode + SubserviceType + phương thức (BR-DB-07) phân biệt 2 thiết bị này bằng gì? | F13: Major (QC đề xuất) | G13: — | H13: QC đã rà — chuyển PO | I13: Co thiết bị Thiết bị IP phone nha | J13: 🔎 QC rà lại 16/10/2026: QC xác nhận có dịch vụ "Thiết bị IP phone", nhưng chưa ai xác nhận SubServiceType 31 có đúng không. Vì khóa chống trùng đã chốt theo 2.2 (CL-XHD-11), rủi ro chuyển sang khóa map tín hiệu BR-DB-07 (vẫn có SubserviceType): tín hiệu giao của Thiết bị Oncall có thể khớp nhầm dòng Thiết bị IP phone. ⇒ Vẫn Open. Nguồn: QC trả lời 16/10/2026 vòng 1 | K13: DOC-v2.0-01 §A.3 (L191-192, L259) + §C#3 (L649-651) | L13: 31 – Thiết bị Oncall (Type 2) 31 – Thiết bị IP phone (Type 2) (...) Ô màu vàng: SubServiceType 31 trùng ở hai dịch vụ (Thiết bị Oncall, Thiết bị IP phone) của nhóm Tổng đài Oncall. | M13: Doc tự đưa vào điểm cần xác nhận. Nếu khóa còn dùng SubServiceType (CL-XHD-11) thì đơn có cả 2 TB này sẽ chỉ ra HĐ cho 1 dòng (SC-XHD-079). | N13: REQ-XHD-002, REQ-XHD-027 | O13: SC-XHD-079 | P13: Open
A14: 10 | B14: CL-XHD-13 | C14: XHD | D14: Ý nghĩa cột Type 1–4 và quan hệ với ProductType DV/TB | E14: Xác nhận nghĩa Type 1–4 và với mỗi Type thì SPF gắn ProductType gì. | F14: Major (QC đề xuất) | G14: — | H14: QC đã rà — chuyển PO | I14: Ghi chú cho QC Danh sách được map (inner join) theo ServiceID giữa bảng dịch vụ và bảng nhóm dịch vụ: 55 dòng, 20 nhóm. Đã loại: ServiceID = 2 (5 dịch vụ, SubServiceType 5-9) vì không có trong bảng nhóm dịch vụ. Đã loại: ServiceID = 22 (GSafe) vì có trong bảng nhóm dịch vụ nhưng chưa có dịch vụ nào. SubServiceType = 31 bị trùng ở 2 dịch vụ (Thiết bị Oncall, Thiết bị IP phone) của nhóm Tổng đài Oncall, đã tô vàng. Cột Type (1-4) chưa có bảng mô tả ý nghĩa, cần PO xác nhận. | J14: 🔎 QC rà lại 16/10/2026: Ghi chú của QC: danh sách dịch vụ được map theo ServiceID giữa bảng dịch vụ và bảng nhóm dịch vụ (55 dòng, 20 nhóm); đã loại ServiceID 2 và 22; SubServiceType 31 trùng ở 2 dịch vụ nhóm Tổng đài Oncall; cột Type (1–4) chưa có bảng mô tả ý nghĩa, cần PO xác nhận. ⇒ Vẫn Open, chuyển PO. Nguồn: QC trả lời 16/10/2026 vòng 1 | K14: DOC-v2.0-01 §C#2 · L644-647 | L14: Ý nghĩa cột Type (1 đến 4) của dịch vụ và cách map với ProductType (DV/TB). Mục A.3, BR-DB-04 Danh sách dịch vụ ghi Type từ 1 đến 4, chưa có mô tả ý nghĩa. | M14: Suy diễn của analyst từ tên dịch vụ: Type 1 = Basic/cước chính, Type 2 = thiết bị, Type 3 = Extra/dịch vụ cộng thêm, Type 4 = triển khai. Nếu đúng thì Type 2 ⇔ TB, còn lại DV — nhưng "Đặt cọc thuê bao (Type 3)" và "Triển khai (Type 4)" là DV hay TB thì không suy được. INVOICE không suy diễn (BR-DB-04) nên ảnh hưởng chủ yếu là dữ liệu test. | N14: REQ-XHD-002, REQ-XHD-009 | O14: — | P14: Open
A15: 11 | B15: CL-XHD-14 | C15: XHD | D15: "Hợp đồng có hiệu lực" và "đang cập nhật" là những giá trị trạng thái nào? | E15: Liệt kê trạng thái đơn = "đang cập nhật" và trạng thái hợp đồng = "có hiệu lực". | F15: Critical | G15: GAP-13 | H15: QC đã rà — chuyển PO | I15: Mô tả trong tài liệu nào tôi chưa tìm ra | J15: 🔎 QC rà lại 16/10/2026: Không tìm thấy mô tả trong tài liệu nào (URD 2.2, flow DOC-v2.0-FIG-03 (ảnh: Workflow ĐỒNG BỘ & XUẤT HÓA ĐƠN TỰ ĐỘNG (v2.0).png)) ⇒ gap tài liệu, vẫn Open, chuyển PO. Nguồn: QC trả lời 16/10/2026 vòng 1 | K15: DOC-v2.0-01 BR-XHD-10 · L425-426 | L15: Đơn không ở trạng thái hủy hoặc đang cập nhật. Thông tin chung phải đủ: hợp đồng có hiệu lực, Sale Team, Sale Channel, tên khách hàng, loại hình khách hàng cấp 1 và cấp 2, địa chỉ xuất hóa đơn, LocationID > 0. | M15: Cần enum trạng thái đơn + hợp đồng để dựng SC-XHD-081, 082 (TP giả định theo v1.0). | N15: REQ-XHD-028, REQ-XHD-029 | O15: SC-XHD-081 | P15: Open | Q15: trạng thái đơn hàng = bình thường và trạng thái hợp đồng bằng bình thường
A16: 12 | B16: CL-XHD-15 | C16: XHD | D16: Log khi không hợp lệ: ghi ở đâu, nội dung gì, thứ tự validate, nhiều lỗi cùng lúc? Đơn không có khuyến mãi? | E16: (1) Log ghi bảng / cột nào, format? (2) Thứ tự kiểm, có log tất cả lỗi hay dừng ở lỗi đầu? (3) Đơn không có KM thì ID KM mang giá trị gì và có bị chặn không? | F16: Major | G16: GAP-29, GAP-30 | H16: QC đã rà — chuyển PO | I16: Mô tả trong tài liệu nào tôi chưa tìm ra | J16: 🔎 QC rà lại 16/10/2026: Không tìm thấy mô tả trong tài liệu nào (URD 2.2, flow DOC-v2.0-FIG-03 (ảnh: Workflow ĐỒNG BỘ & XUẤT HÓA ĐƠN TỰ ĐỘNG (v2.0).png)) ⇒ gap tài liệu, vẫn Open, chuyển PO. Nguồn: QC trả lời 16/10/2026 vòng 1 | K16: DOC-v2.0-01 BR-XHD-10 · L427-428 | L16: Chi tiết từng dịch vụ phải có các ID dịch vụ, nhóm dịch vụ, gói dịch vụ, chính sách, câu lệnh giá, chương trình khuyến mãi > 0. Không hợp lệ thì không phát hành và ghi log; hệ thống không giữ chờ phát hành lại vì hóa đơn phải lập trong ngày. | M16: 14 SC negative (SC-XHD-080..095) chỉ kiểm được "có log". Đơn không có chương trình khuyến mãi thì ID KM = 0? ⇒ theo chữ URD sẽ bị chặn. | N16: REQ-XHD-029, REQ-XHD-030, REQ-XHD-031 | O16: SC-XHD-095 | P16: Open | Q16: Chi tiết từng dịch vụ phải có các ID dịch vụ, nhóm dịch vụ, gói dịch vụ, chính sách, câu lệnh giá, chương trình khuyến mãi > 0. có thể xem ở Web admin QC không có quyền vào xem log
A17: 13 | B17: CL-XHD-16 | C17: XHD | D17: Job cảnh báo 15 phút: điều kiện, kênh gửi, người nhận, nội dung? | E17: Job cảnh báo những dòng nào, gửi qua kênh nào (mail?), cho ai, nội dung gì? Có thuộc v2.0 không? | F17: Critical | G17: GAP-31 | H17: QC đã rà — chuyển PO | I17: Mô tả trong tài liệu nào tôi chưa tìm ra | J17: 🔎 QC rà lại 16/10/2026: Không tìm thấy mô tả trong tài liệu nào (URD 2.2, flow DOC-v2.0-FIG-03 (ảnh: Workflow ĐỒNG BỘ & XUẤT HÓA ĐƠN TỰ ĐỘNG (v2.0).png)) ⇒ gap tài liệu, vẫn Open, chuyển PO. Nguồn: QC trả lời 16/10/2026 vòng 1 | K17: DOC-v2.0-01 BR-XHD-10 · L429 | L17: Job cảnh báo chạy 15 phút một lần để bổ sung thông tin kịp trước giờ chốt. | M17: Nằm trong BR in-scope nhưng không có đặc tả — SC-XHD-097 để P3. | N17: REQ-XHD-032 | O17: SC-XHD-097 | P17: Open
A18: 14 | B18: CL-XHD-18 | C18: XHD | D18: Billing lỗi / timeout: hệ thống làm gì? | E18: Retry? Giữ rỗng chờ đợt sau? Cảnh báo? | F18: Critical | G18: GAP-14 | H18: QC đã rà — chuyển PO | I18: Mô tả trong tài liệu nào tôi chưa tìm ra | J18: 🔎 QC rà lại 16/10/2026: Không tìm thấy mô tả trong tài liệu nào (URD 2.2, flow DOC-v2.0-FIG-03 (ảnh: Workflow ĐỒNG BỘ & XUẤT HÓA ĐƠN TỰ ĐỘNG (v2.0).png)) ⇒ gap tài liệu, vẫn Open, chuyển PO. Nguồn: QC trả lời 16/10/2026 vòng 1 | K18: DOC-v2.0-01 BR-XHD-13 · L439 | L18: Phát hành qua Billing System, ghi BillNumber và BillDate vào giỏ tồn xuất hóa đơn | M18: Không có nhánh lỗi. TP giả định giữ BillNumber rỗng + log (SC-XHD-104). | N18: REQ-XHD-035 | O18: SC-XHD-104 | P18: Open
A19: 15 | B19: CL-XHD-19 | C19: XHD | D19: Cột Note: thuộc bảng nào, format log tín hiệu giao hàng? | E19: Cột Note ở bảng nào, ghi những trường gì của tín hiệu, có ghi lý do (đã có HĐ / không khớp) không? | F19: Major | G19: GAP-27 | H19: Chưa trả lời | K19: DOC-v2.0-01 BR-DB-07 · L375 | L19: Nếu thiết bị đã có hóa đơn hoặc không khớp khóa thì không ghi nhận, chỉ ghi log nội dung tín hiệu vào cột Note. | M19: SC-XHD-026..028 chỉ kiểm định tính. | N19: REQ-XHD-013 | O19: — | P19: Open | Q19: QC không có quyền vào xem log
A20: 16 | B20: CL-XHD-20 | C20: XHD | D20: Bản tin Order Event lỗi giải mã / thiếu trường | E20: Bản tin không giải mã được / thiếu trường bắt buộc thì bỏ qua + log, hay dừng consumer? | F20: Major | G20: GAP-26 | H20: QC đã rà — chuyển PO | I20: Không thấy mô tả ở file Invoice_Issuance_Architecture_v2_2_URD_v2_0_1310 | J20: 🔎 QC rà lại 16/10/2026: URD 2.2 không mô tả ⇒ gap tài liệu, vẫn Open, chuyển PO. Nguồn: QC trả lời 16/10/2026 vòng 1 | K20: DOC-v2.0-01 §I.a Trigger · L332 *(derived from omission — URD không nói)* | L20: Sự kiện đơn hàng từ SPF; tín hiệu giao hàng hoàn tất; worker chạy theo lịch (BR-XHD-01). | M20: URD 2.2 không có nhánh lỗi khi nhận / giải mã bản tin. Chưa sinh SC. | N20: — | O20: — | P20: Open | Q20: 1 đơn hàng đều có cac thông tin bắt buộc nên sẽ không có TH nhận bản tin lỗi, trường hợp nếu lỗi thì là bug
A21: 17 | B21: CL-XHD-21 | C21: XHD | D21: BR-XHD-18 "clear thuê thiết bị đầu cuối": có thuộc v2.0? Đặc tả? | E21: Flow v2.0 đã đưa BR-XHD-18 vào bước phát hành. Cần đặc tả: DVKH HO thao tác ở đâu (màn / tool nào; có phải cột "Clear thiết bị đầu cuối" trên màn Liệt kê cước — FIG-02 (ảnh: Danh sách hóa đơn của Hợp đồng.png) không), trước hay sau khi phát hành, và kết quả trên HĐ (bỏ dòng "thuê thiết bị đầu cuối" / đổi nội dung / lập HĐ điều chỉnh)? | F21: BLOCKING | G21: GAP-53 | H21: Chưa trả lời | J21: 🔎 Bổ sung 16/10/2026 từ flow §B.I.b — DOC-v2.0-FIG-03 (ảnh: Workflow ĐỒNG BỘ & XUẤT HÓA ĐƠN TỰ ĐỘNG (v2.0).png), bước "Phát hành hóa đơn · BR-XHD-13, 14, 18" (ô tô màu = "Nội dung mới, đã sửa hoặc cần xác nhận"): DVKH HO clear được "thuê TB đầu cuối". Flow v2.0 đã đặt BR-XHD-18 trong luồng phát hành và ghi rõ đây là nội dung cần xác nhận ⇒ phần "thuộc v2.0" coi như có, nhưng vẫn chưa có đặc tả ⇒ giữ ⛔ BLOCKING cho REQ-XHD-039. | K21: DOC-v2.0-01 BR-XHD-18 · L449-452 | L21: Bổ sung chức năng cho phép DVKH HO chủ động xử lý với hợp đồng có yêu cầu clear nội dung "thuê thiết bị đầu cuối" trên hóa đơn. Mới (kịp plan các chức năng chính sẽ thự hiện) [Ảnh màn hình hiện hữu — có sẵn cột cùng tên — DOC-v2.0-FIG-02 (ảnh: Danh sách hóa đơn của Hợp đồng.png) màn "LIỆT KÊ CƯỚC CỦA THUÊ BAO" · tiêu đề cột cuối bảng] Clear thiết bị đầu cuối | M21: Có thể có UI (duy nhất trong URD). Màn "Liệt kê cước" của Hệ thống Thông tin (FIG-02 (ảnh: Danh sách hóa đơn của Hợp đồng.png)) đã có cột "Clear thiết bị đầu cuối" cạnh "Hóa đơn điều chỉnh giảm", "Hóa đơn thay thế", "Gen hóa đơn" ⇒ suy diễn của analyst: BR-XHD-18 có thể là thao tác trên màn này, nhưng URD không nói. REQ-XHD-039 chưa có SC. | N21: REQ-XHD-039 | O21: — | P21: Open | Q21: chưa chốt có thực hiện không để hỏi lại PM
A22: 18 | B22: CL-XHD-22 | C22: XHD | D22: Mail cảnh báo bản tin trễ qua ngày + phương án xử lý: thuộc v2.0? Đặc tả? | E22: Mail cảnh báo có trong v2.0? Điều kiện phát hiện, lịch gửi, người nhận, nội dung? Phương án xử lý dòng trễ đã chốt chưa? | F22: BLOCKING | G22: GAP-02, GAP-11 | H22: Chưa trả lời | K22: DOC-v2.0-01 §D#3 · L666-669 | L22: Bản tin đồng bộ về chậm qua ngày, dòng không được luồng nào xử lý. RISK-01 PM và SA xử lý; mail cảnh báo là yêu cầu bắt buộc đã thống nhất. | M22: Phụ lục ghi "không cần PO confirm" nhưng là "yêu cầu bắt buộc". REQ-XHD-042 chưa có SC; SC-XHD-045 chỉ ghi nhận hiện trạng. | N22: REQ-XHD-015, REQ-XHD-042 | O22: SC-XHD-045 | P22: Open | Q22: check lại RISK-01 của URD v2.1
A23: 19 | B23: CL-XHD-23 | C23: XHD | D23: Phương án chặn phát hành trùng worker ↔ realtime | E23: Phương án đã chốt? Ngày có trên STG? | F23: Critical | G23: GAP-12 | H23: Chưa trả lời | K23: DOC-v2.0-01 §D#2 · L662-665 | L23: Rủi ro phát hành hóa đơn trùng khi worker và realtime chạy song song. BR-XHD-09 PM và SA chốt phương án kỹ thuật. | M23: RISK-XHD-02. Không có phương án ⇒ không biết expected khi 2 luồng tranh nhau. | N23: REQ-XHD-027 | O23: — | P23: Open | Q23: Check lai BR-XHD-09 của URD v2.1
A24: 20 | B24: CL-XHD-24 | C24: XHD | D24: Cutover v1 → v2: có test trên STG không? Dữ liệu luồng cũ? | E24: Cutover có nằm trong phạm vi QC v2.0? Nếu có: STG có dữ liệu + service luồng cũ không? | F24: Major | G24: GAP-32 | H24: Chưa trả lời | K24: DOC-v2.0-01 §D#1 · L658-661 | L24: Chuyển đổi hệ thống v1 sang v2 (cutover, giai đoạn giao thoa, quét tay bổ sung). BR-DB-08 PM, SA | M24: TP giữ FR06 (P2, 18 TC). Out-scope ⇒ SC-XHD-107, 108 chuyển DEPRECATED và RISK-XHD-10 → Closed. | N24: REQ-XHD-041 | O24: SC-XHD-107 | P24: Open | Q24: Check lai BR-DB-08 của URD v2.1
A25: 21 | B25: CL-XHD-25 | C25: XHD | D25: Đơn bán thêm: rule áp chung, hay có điểm khác? | E25: Mọi BR áp chung cho đơn bán thêm? Nếu không, liệt kê điểm khác. | F25: Major | G25: GAP-60 | H25: Chưa trả lời | K25: DOC-v2.0-04 mail PM · dòng 3 ↔ DOC-v2.0-01 (toàn bộ BR — không có từ "bán thêm") | L25: - Bán mới, Bán thêm => ok | M25: Ảnh hưởng ≥7 chức năng (XHD F01, F04, F06; GN F17; HK F19, F23; F27). Điểm có thể khác: PĐK (CL-XHD-07), cọc (CL-GN-07), ký hiệu HĐ (CL-HK-01), tiền trả trước (CL-HK-07). | N25: REQ-XHD-040 | O25: SC-XHD-106 | P25: Open | Q25: áp đụng cho bán mới và bán thêm
A26: 22 | B26: CL-XHD-26 | C26: XHD | D26: Ma trận kênh × nhóm DV × loại đơn thực bán | E26: Gửi ma trận kênh × nhóm DV × {bán mới, bán thêm} thực bán; cặp nào không bán thì bỏ khỏi phạm vi test. | F26: Major | G26: GAP-62 | H26: Chưa trả lời | K26: DOC-v2.0-01 §A.2 (L80) + §A.3 (L139) + BR-XHD-12 (L435) | L26: Tất cả kênh bán trong danh sách dưới đây thuộc phạm vi. Phase 1 đã triển khai Shopee và Tiktok. (...) Chi nhánh nào được bán sản phẩm dịch vụ nào do bên quản lý sản phẩm bổ sung thuộc tính, nằm ngoài URD này. | M26: SC-XHD-001..017 giả định mọi kênh bán mọi nhóm. Mỗi cặp không bán bớt 2 TC (TP §2.3). | N26: REQ-XHD-001, REQ-XHD-002 | O26: — | P26: Open | Q26: phần này chờ trao đổi lại nha
A27: 23 | B27: CL-XHD-27 | C27: XHD | D27: Danh mục HT triển khai (DOC-v2.0-05): map sang 3 nguồn tín hiệu; TB "Không" phát hành thế nào? | E27: (1) TB "Không" xuất HĐ theo đường nào? (2) Đơn mix: tín hiệu mang phương thức nào? (3) File này có phải danh mục chính thức của v2.0 không? | F27: Major (QC đề xuất) | G27: — | H27: Chưa trả lời | K27: DOC-v2.0-05 sheet "1. HT Triển khai" · STT 1, 8 ↔ DOC-v2.0-01 BR-DB-02 (L349) | L27: [DOC-v2.0-05 — STT 8 — cột D] - Phiếu thi công: triển khai bởi TINPNC nếu hàng hóa có mix HT "Không" và "TIN/PNC" - None: không đẩy triển khai, giao hàng nếu hàng hóa, dịch vụ trên đơn hàng chỉ có "Không" [DOC-v2.0-05 — STT 1 — cột G] Đơn hàng có ít nhất 1 SPDV có mix HT Triển khai TIN/PNC và Quầy/ Sales --> auto xử lý theo luồng triển khai TINPNC [URD 2.2 BR-DB-02 — L349] Tín hiệu đi thẳng về INVOICE từ 3 nguồn độc lập: phiếu thi công (tình trạng "Đã xử lý hoàn tất"), Vendor (khi đối tác giao xong), phiếu giao tại quầy. | M27: File bổ sung có 8 hình thức, URD chỉ nói 3 nguồn. (1) TB DeployType "Không" ⇒ không có phiếu ⇒ không có tín hiệu ⇒ theo BR-XHD-03 không bao giờ phát hành. (2) Đơn mix TIN/PNC + Quầy gộp sang TINPNC ⇒ phương thức trong khóa (BR-DB-07, BR-XHD-08) là gì. (3) File chưa có version/ngày, chưa rõ là tài liệu chính thức hay tham khảo. | N27: REQ-XHD-004, REQ-XHD-043 | O27: SC-XHD-109 | P27: Open | Q27: Thiết bị/dv không có triển khai thì vẫn được xuất hóa đơn khi đơn hàng hoàn tất , đơn hàng mic đành cho 1 đơn hàng có hình thức Phiếu thi công:
A28: 24 | B28: CL-XHD-28 | C28: XHD | D28: Ảnh màn Hệ thống Thông tin (DOC-v2.0-FIG-01 (ảnh: Chi tiết hóa đơn.png), FIG-02 (ảnh: Danh sách hóa đơn của Hợp đồng.png)) vẫn hiện "Từ ngày / Đến ngày" — 2 màn này dùng để verify? | E28: Hai màn này có phải điểm verify HĐ v2.0 không (QC có quyền truy cập STG)? Với HĐ v2.0, ô From/To và dòng "Khoản" hiển thị gì; cột "CN" là chi nhánh xuất HĐ của BR-XHD-12? | F28: Minor (QC đề xuất) | G28: — | H28: Chưa trả lời | K28: DOC-v2.0-FIG-01 (ảnh: Chi tiết hóa đơn.png) màn "CHI TIẾT CỦA HÓA ĐƠN U25SG00002918" · ô "Cước phí từ ngày (From)" / "Đến ngày (To)" · dòng Chi tiết #1 ↔ DOC-v2.0-01 BR-XHD-13 (L441) | L28: [Ảnh màn hình hiện hữu — DOC-v2.0-FIG-01 (ảnh: Chi tiết hóa đơn.png)] Cước phí từ ngày (From) 17/11/2025 · Đến ngày (To) 16/12/2025 Khoan thu tu 17/11/2025 den 16/12/2025 [URD 2.2 — L441] Nội dung hiển thị trên hóa đơn là tên dịch vụ + số tháng sử dụng (lấy từ SPF), không hiển thị kỳ hạn từ ngày – đến ngày. | M28: Hai ảnh là cùng HĐ U25SG00002918 năm 2025 (trước Phase 2) trên "Hệ thống Thông tin": FIG-01 (ảnh: Chi tiết hóa đơn.png) tab "Chi tiết của Hóa đơn", FIG-02 (ảnh: Danh sách hóa đơn của Hợp đồng.png) tab "Báo cáo tổng hợp" → "Liệt kê cước của thuê bao" (cột Hóa đơn, Ngày Phát Hành, CN, Loại hóa đơn, Số tiền, Đã TT, Gen hóa đơn…). Nhiều khả năng đây là điểm verify BillNumber / BillDate / chi nhánh / Payment của QC — nhưng chưa ai xác nhận. Nếu dùng để verify HĐ v2.0 thì cần biết ô From/To sẽ hiển thị gì. | N28: REQ-XHD-036 | O28: — | P28: Open | Q28: Check số tháng , thông tin khách hàng , số tiền, tình trạng thanh toán, thông tin dịch vụ . Fromdate, todate trên đầu hóa đơn lấy nào cũng được miễn là fromdate-todate có trong detail , Khoản hiển thị " Khoản thu từ fromdate đén todate. CN hiển thị CN của HD Nội dung hiển thị trên hóa đơn là tên dịch vụ HIERN THỊ TRONG THÔNG TIN CHI TIẾT LOẠI DỊCH VỤ, SỐ THÁNG MÀ TÍNH RA KỲ HẠN
A29: 25 | B29: CL-XHD-29 | C29: XHD | D29: Tài liệu tích hợp: payload Kafka, schema bảng, API, enum | E29: Gửi SDD / API spec / schema các bảng OB_OrderRaw*, OB_OrderBill*, Paid, Payment, cọc + enum trạng thái; điền owner + ngày chốt cho §C. | F29: BLOCKING | G29: GAP-07, GAP-09 | H29: Chưa trả lời | K29: DOC-v2.0-01 §D · L653 | L29: Các nội dung dưới đây không cần PO confirm và không còn nằm trong phần chính. Chi tiết xem URD v2.1. | M29: Ảnh hưởng cả GN (Kafka Out, API kênh thanh toán, API EVC, enum paymentstatus) và HK (API HĐĐT, Dịch vụ). §C của 2.2 không có owner / ngày chốt (GAP-09). | N29: REQ-XHD-011, REQ-XHD-037 | O29: SC-XHD-040 | P29: Open | Q29: Chờ hỏi lại BA
A30: 26 | B30: CL-XHD-30 | C30: XHD | D30: Đơn ngoài 17 kênh / dịch vụ ngoài danh sách (ServiceID 2, 22) đi vào INVOICE thì xử lý thế nào? | E30: Đơn có SaleChannelID / ServiceID ngoài danh sách thì INVOICE bỏ qua (không xuất) hay vẫn xuất? | F30: Minor (QC đề xuất) | G30: — | H30: Chưa trả lời | K30: DOC-v2.0-01 §A.3 · L260 | L30: Không có trong danh sách phạm vi: ServiceID 2 (SubServiceType 5 đến 9) vì không có trong bảng nhóm dịch vụ; ServiceID 22 (GSafe) vì chưa có dịch vụ nào. | M30: URD chỉ nói "không thuộc phạm vi", không nói hệ thống bỏ qua, log hay vẫn xuất. TP ghi ServiceID 2, 22 ngoài phạm vi test ⇒ chưa sinh SC; hỏi để biết có cần negative test chặn không. | N30: REQ-XHD-002 | O30: — | P30: Open | Q30: BỎ QUA KHÔNG TEST
A31: 27 | B31: CL-XHD-31 | C31: XHD | D31: URD v1.0 (Phase 1) và các "điều chỉnh v2.0" của Shopee / Tiktok | E31: Gửi URD v1.0 + liệt kê hành vi Phase 1 của Shopee/Tiktok giữ / đổi ở v2.0. | F31: Major | G31: GAP-24 | H31: Chưa trả lời | K31: DOC-v2.0-01 §A.4 #2 (L269-270) + §A.2 (L133, L137) | L31: URD v1.0 v1.0 (nền tảng, rule kênh TMĐT). (...) Đã triển khai ver1.0Có điều chinh ver2.0 | M31: Không có URD v1.0 ⇒ hồi quy TMĐT (SC-XHD-016, 017, 029, 060) theo giả định. | N31: REQ-XHD-005, REQ-XHD-020 | O31: — | P31: Open | Q31: VẪN TEST NHA
A32: 28 | B32: CL-XHD-32 | C32: XHD | D32: Dòng cuối tháng chuyển sang tháng sau: đợt nào phát hành, BillDate ngày nào? | E32: Dòng đủ điều kiện sau giờ chốt cuối ngày cuối tháng được phát hành ở đợt nào của tháng sau (đợt 1 ngày 1? realtime đầu ngày?), BillDate là ngày nào, và cơ chế nào đưa dòng này vào phạm vi quét khi mốc nghiệp vụ thuộc ngày trước? | F32: Critical (QC đề xuất) | G32: — | H32: Mới (phát sinh vòng 1) | K32: DOC-v2.0-01 BR-XHD-01 (L384) ↔ BR-XHD-01 (L385) | L32: [BR-XHD-01 — phạm vi quét của worker — L384] Mỗi đợt quét các dòng chưa xuất hóa đơn có mốc nghiệp vụ trong ngày, trước giờ chốt của đợt. [BR-XHD-01 — dòng cuối tháng — L385] Đơn đủ điều kiện sau giờ chốt cuối của ngày cuối tháng sẽ phát hành sang tháng sau, ảnh hưởng kỳ ghi nhận doanh thu. | M32: Dòng này có mốc nghiệp vụ ngày cuối tháng. Sang ngày 1 tháng sau, worker chỉ quét dòng có mốc trong ngày ⇒ theo chữ L384 thì không đợt nào lấy dòng này — cùng khoảng trống với RISK-XHD-03 (bản tin trễ qua ngày). SC-XHD-046 chỉ kiểm được "không phát hành trong tháng". | N32: REQ-XHD-015, REQ-XHD-016 | O32: SC-XHD-046 | P32: Open | Q32: NGÀY 1, CẦN pm confirm lại, BillDate lấy ngày phát hành
A33: 29 | B33: CL-XHD-33 | C33: XHD | D33: Phụ lục D của URD 2.2 trỏ chi tiết sang tài liệu không còn sử dụng — chưa có đặc tả | E33: URD 2.2 Phụ lục D ghi "Chi tiết xem URD v2.1" nhưng tài liệu này không còn được sử dụng. PO / SA cung cấp tài liệu thay thế cho các mục D#1–D#3 (cutover, chống phát hành trùng, bản tin trễ + mail cảnh báo), hoặc xác nhận mục nào ngoài phạm vi test v2.0? Đồng thời định nghĩa "mốc nghiệp vụ" của dòng DV và dòng TB (thời điểm thanh toán / thời điểm giao hàng?). | F33: Critical (QC đề xuất) | G33: — | H33: Mới (phát sinh vòng 1) | K33: DOC-v2.0-01 §D · L653 + §D#1–#3 (L658-669) | L33: Các nội dung dưới đây không cần PO confirm và không còn nằm trong phần chính. Chi tiết xem URD v2.1. | M33: Từ 16/10/2026 QC owner xác nhận URD 2.1 đã out, không dùng ⇒ các mục sau chưa có đặc tả: (1) D#1 cutover — cơ chế kiểm tra chéo luồng cũ / mới (SC-XHD-107, 108 đã deprecated; CL-XHD-24); (2) D#2 phương án chống phát hành trùng worker ↔ realtime (CL-XHD-23); (3) D#3 bản tin trễ qua ngày + mail cảnh báo (CL-XHD-22); (4) định nghĩa "mốc nghiệp vụ" của dòng DV / TB — BR-XHD-01 L384 và BR-XHD-02 L393 dùng nhưng 2.2 không định nghĩa. Phần GN (D#4) ở CL-GN-10; HK (D#5, D#6) ở CL-HK-10. | N33: REQ-XHD-041, REQ-XHD-042 | O33: SC-XHD-107 | P33: Open | Q33: Vẫn sử dụng nếu phần này tôi hỏi PM và PM yefu cầu test
... A36: 32 | B36: CL-GN-03 | C36: GN | D36: "Kênh sàn" gồm những SaleChannelID nào? | E36: Kênh sàn (được gạch nợ tạm) = chỉ Shopee (20) + Tiktok (21)? Có kênh nào khác? | F36: Major (QC đề xuất) | G36: — | H36: Chưa trả lời | K36: DOC-v2.0-01 BR-NT-01 (L493) ↔ §A.2 (L79-137) | L36: [URD 2.2 — L493] Chỉ gạch nợ tạm khi Paid ở trạng thái gạch nợ tạm và đơn thuộc kênh bán qua sàn (khách thanh toán với sàn nên tiền chưa chắc về công ty). | M36: §A.2 không có cột đánh dấu kênh sàn. Momo (17), MBBank (12), TGDD (14), API (7) cũng là kênh khách thanh toán qua bên thứ ba — không rõ có tính là sàn. Giả định {20, 21} theo URD 2.2 §A.1 L59 ("kênh TMĐT (Shopee, TikTok Shop)"). | N36: REQ-GN-005, REQ-GN-009 | O36: — | P36: Open | Q36: Chỉ shoppe và TikTok Shop
A37: 33 | B37: CL-GN-04 | C37: GN | D37: Enum paymentstatus và mã "phương thức thanh toán đặc biệt" | E37: Liệt kê enum paymentstatus và mã phương thức thanh toán đặc biệt dùng cho gạch nợ tạm. | F37: Critical | G37: GAP-07 | H37: Chưa trả lời | K37: DOC-v2.0-01 §A.5 #6 (L300) + BR-NT-02 (L498) | L37: Trường paymentstatus quyết định gạch nợ tạm hay gạch nợ thật. (...) Ghi Payment bằng phương thức thanh toán đặc biệt, số tiền bằng toàn bộ nợ còn lại. | M37: Cần giá trị cụ thể để dựng dữ liệu SC-GN-011..013, 019 và phân biệt Payment tạm với Payment thật khi verify gỡ tạm. Có trạng thái nào khác "tạm" / "hoàn tất" (vd hủy, hoàn tiền) không? | N37: REQ-GN-005, REQ-GN-010, REQ-GN-011 | O37: — | P37: Open
A38: 34 | B38: CL-GN-05 | C38: GN | D38: "Mỗi bill chỉ gạch một lần" vs gạch từng phần — bill gạch thiếu có được gạch tiếp khi có Paid mới? | E38: Bill đã gạch một phần, khi Paid mới về (đợt thanh toán sau) có được gạch tiếp không? | F38: Major (QC đề xuất) | G38: — | H38: Chưa trả lời | K38: DOC-v2.0-01 BR-GN-01 (L509) ↔ BR-GN-04 (L518-519) | L38: [BR-GN-01 — L509] Chỉ gạch bill còn nợ; mỗi bill chỉ gạch một lần. [BR-GN-04 — L518-519] Mỗi lần gạch = nhỏ nhất của số dư Paid và nợ còn lại; ghi Payment, trừ Paid, đẩy Kafka Out về kênh thanh toán. Dừng khi hết nợ hoặc hết Paid; Paid dư được giữ lại. | M38: Đọc đúng chữ thì bill gạch thiếu ở SC-GN-031 sẽ không bao giờ được gạch tiếp. Suy diễn của analyst: "một lần" nghĩa là không gạch lại cùng khoản Paid, còn Paid mới vẫn gạch tiếp được — cần xác nhận. | N38: REQ-GN-012, REQ-GN-014 | O38: — | P38: Open | Q38: SỐ TIỀN CẦN THANH TOÁN PHẢI BẰNG SỐ TIỀN GẠCH SAU KHI GẠCH BILL XONG HỆ THỐNG CHUYỂN SANG TRẠNG THÁI ĐÃ THANH TOÁN => KHÔNG THỂ GẠCH NỮA
A39: 35 | B39: CL-GN-06 | C39: GN | D39: Gỡ gạch tạm rồi Paid hoàn tất nhỏ hơn nợ: HĐ quay về "còn nợ" — có hệ quả / cảnh báo? | E39: Khi Paid quyết toán của sàn nhỏ hơn nợ, phần chênh xử lý thế nào (Paid phí TMĐT? để còn nợ?) | F39: Major (QC đề xuất) | G39: — | H39: Chưa trả lời | K39: DOC-v2.0-01 BR-NT-04 · L503 | L39: Khi Paid chuyển sang thanh toán hoàn tất, nếu hóa đơn đã gạch nợ tạm thì gỡ Payment tạm trước (hóa đơn trở lại còn nợ) rồi mới gạch nợ thật. | M39: Sàn quyết toán có thể trừ phí ⇒ Paid hoàn tất < nợ. HĐ từ "Đã gạch nợ" về "còn nợ" — downstream (hậu kỳ, báo cáo) có bị ảnh hưởng? Phí TMĐT là một PaidType — có được dùng để gạch phần chênh không? | N39: REQ-GN-011 | O39: SC-GN-024 | P39: Open | Q39: Chờ hỏi lại BA
A40: 36 | B40: CL-GN-07 | C40: GN | D40: Danh mục loại cọc ↔ dịch vụ; đơn bán thêm dùng cọc nào? | E40: Danh mục loại cọc + dịch vụ dùng loại nào; đơn bán thêm có dùng chung cọc của hợp đồng không? | F40: Major | G40: GAP-60 | H40: Chưa trả lời | K40: DOC-v2.0-01 BR-GC-02 (L534) + BR-GC-03 (L539) | L40: Cọc của hợp đồng theo từng loại phải đủ cho các dịch vụ dùng loại cọc đó trên bill. (...) Mỗi dịch vụ trừ đúng loại cọc của nó; nhiều dịch vụ cùng loại cọc gom thành một dòng Payment. | M40: URD 2.2 không nói loại cọc của dịch vụ lưu ở đâu. Cần danh mục để dựng SC-GN-039..042. SubServiceType 25 "Đặt cọc thuê bao" (§A.3) có liên quan không? | N40: REQ-GN-017, REQ-GN-018 | O40: SC-GN-050 | P40: Open | Q40: Đơn hàng bán mới bán thêm đều có cọc, sau khi thanh toán xong khoản thu chuyển sang đã thanh toán xong đảy thông tin qua đặt cọc Đặt cọc có nhiểu loại khác nhau như Đặt cọc trừ đân, đặt cọc hợp đồng , đặt cọc thiết bị
A41: 37 | B41: CL-GN-08 | C41: GN | D41: Nhánh Paid: thứ tự giữa đội EVC gạch EVC và INVOICE gạch tiền khách? | E41: Ở nhánh Paid, INVOICE có phải chờ đội EVC gạch phần EVC (không lock) xong mới gạch tiền khách không? Nếu không, INVOICE có chừa phần EVC không lock không? | F41: Critical (QC đề xuất) | G41: — | H41: Chưa trả lời | K41: DOC-v2.0-01 BR-VC (L545-546) | L41: [URD 2.2 — L545-546] Phần gạch nợ bằng EVC do đội EVC thực hiện; ISC tự quyết phương thức quản trị và xử lý voucher. Với EVC bị lock (khách chưa ký hợp đồng), INVOICE chừa phần lock khi gạch tiền khách | M41: 2.2 không giữ câu "gạch EVC trước". Nếu INVOICE gạch tiền khách trước khi đội EVC gạch (EVC không lock) ⇒ tiền khách cover luôn phần EVC, Paid khách bị dùng thừa, đội EVC không còn nợ để gạch. Chỉ phần lock được chừa ra theo 2.2. | N41: REQ-GN-019 | O41: — | P41: Open
A42: 38 | B42: CL-GN-09 | C42: GN | D42: Hai bill bằng tiền nhau: thứ tự gạch? | E42: Bill bằng tiền thì ưu tiên theo BillDate / BillNumber? | F42: Low | G42: — | H42: Chưa trả lời | K42: DOC-v2.0-01 BR-GN-03 · L513 | L42: Một đơn có 1..n bill; gạch từng bill, theo số tiền từ cao xuống thấp. | M42: Chỉ ảnh hưởng khi Paid / cọc không đủ cho cả 2 bill. SC-GN-030 để P3. | N42: REQ-GN-013 | O42: SC-GN-030 | P42: Open | Q42: 1 ĐƠN CÓ NHIỂU BILL THÌ ƯU TIÊN GẠCH NỢ HÓA ĐƠN CÓ SỐ HIỂN CAO NHẤT THEO BillNumber
A43: 39 | B43: CL-GN-10 | C43: GN | D43: Chi tiết gạch nợ URD 2.2 chuyển sang Phụ lục D#4 — chưa có đặc tả | E43: Phụ lục D#4 của URD 2.2 chưa có đặc tả. PO / đội EVC cung cấp: (1) danh mục PaidType và mã voucher; (2) nguồn / API lấy tổng EVC và tiền lock, loại EVC nào có lock; (3) bảng / trường lưu tồn cọc và loại cọc của từng dịch vụ? | F43: Critical (QC đề xuất) | G43: — | H43: Mới (phát sinh vòng 1) | K43: DOC-v2.0-01 §D#4 · L671-673 | L43: Cấu hình EVC: PaidType, Owner gạch, trần 50%, EVC bị lock chi tiết. BR-VC-01 đến 07, BR-GC-04 đến 07 Đội EVC thực hiện; một số bước đã đánh dấu bỏ. | M43: Phụ lục D của URD 2.2 trỏ chi tiết về tài liệu không còn sử dụng ⇒ chưa có: danh mục PaidType; nguồn tổng EVC + tiền lock và loại EVC nào có lock (CL-GN-02); bảng tồn cọc và nơi ghi loại cọc của dịch vụ (CL-GN-07); nghĩa của "mỗi bill chỉ gạch một lần" (CL-GN-05); thứ tự đội EVC gạch (CL-GN-08). Phần URD 2.2 tự đủ, vẫn dùng: cọc theo hợp đồng (L529, L534), mỗi dịch vụ trừ đúng loại cọc, gom dòng Payment theo loại cọc (L539). | N43: — | O43: — | P43: Open
...

Sheet Đã chốt vòng 1
A1: CÂU ĐÃ CHỐT SAU VÒNG 1 (16/10/2026) — để PO / BA xác nhận lại nếu không đồng ý
A3: Mã câu hỏi | B3: Module | C3: Nội dung | D3: Trả lời vòng 1 (QC) | E3: Kết luận đã cập nhật vào analyze
A4: CL-XHD-06 | B4: XHD | C4: Ngày cuối tháng, đủ điều kiện sau giờ chốt cuối: realtime phát hành ngay hay để sang tháng sau? | D4: ví dụ ngày ngày 30 cuối tháng tới 11h30 mới đủ dk phát hành hóa đơn thì sẽ phát hành sang tháng sau | E4: ✅ RESOLVED 16/10/2026 — Ngày cuối tháng, dòng đủ điều kiện sau giờ chốt cuối ⇒ không phát hành trong tháng, phát hành sang tháng sau — đúng câu BR-XHD-01 L385. Đây là ngoại lệ của realtime "xử lý ngay khi nhận" (BR-XHD-06 L413) cho ngày cuối tháng. QC lấy ví dụ: ngày cuối tháng, tới sau giờ chốt cuối mới đủ điều kiện ⇒ HĐ thuộc tháng sau. Nguồn: QC trả lời 16/10/2026 vòng 1. Phát sinh câu hỏi mới về đợt phát hành ở tháng sau → CL-XHD-32. SC-XHD-046 đổi Then.
A5: CL-XHD-09 | B5: XHD | C5: Revision 2.2 ghi thêm "KH Chuỗi/Dự án" vào BR-XHD-03 nhưng BR không có nội dung | D5: KH Chuỗi không có rule phát hành riêng do tôi thấy URD không có mô tả chỗ này | E5: ✅ RESOLVED 16/10/2026 — KH Chuỗi không có rule phát hành riêng: URD không mô tả nội dung nào. "Dự án" trong Revision History ứng với câu hợp đồng con / hợp đồng dự án đã có ở BR-XHD-03 L401. Không sinh SC. Nguồn: QC trả lời 16/10/2026 vòng 1. Nếu PO bổ sung rule cho KH Chuỗi ⇒ mở lại CL này.
A6: CL-XHD-10 | B6: XHD | C6: BR-XHD-04 (autobill TB theo phương thức) đã bỏ — bỏ hành vi hay chỉ bỏ câu chữ? | D6: Khi nhận tín hiệu giao hàng của một phương thức, INVOICE phát hành chỉ TB có trong tín hiệu theo như mô tả BR-XHD-06 | E6: ✅ RESOLVED 16/10/2026 — Khi nhận tín hiệu giao hàng của một phương thức, INVOICE chỉ phát hành TB có trong tín hiệu, không phát hành toàn bộ TB của phương thức. Căn cứ: BR-XHD-06 L412; tín hiệu map vào từng TB theo khóa có SubserviceType + phương thức (BR-DB-07 L374); flow DOC-v2.0-FIG-03 (ảnh: Workflow ĐỒNG BỘ & XUẤT HÓA ĐƠN TỰ ĐỘNG (v2.0).png) ghi "realtime tách theo tín hiệu". Nguồn: QC trả lời 16/10/2026 vòng 1. Thêm SC-XHD-110.
A7: CL-XHD-17 | B7: XHD | C7: Dòng không hợp lệ được bổ sung thông tin: đợt sau có phát hành? | D7: Theo file Invoice_Issuance_Architecture_v2_2_URD_v2_0 , file Invoice_Issuance_Architecture_v2_0_URD_v1_0 là bảng URD cũ | E7: ✅ RESOLVED 16/10/2026 — Theo URD 2.2: dòng bị chặn chỉ còn cơ hội phát hành trong cùng ngày. Đợt worker sau quét "dòng chưa xuất hóa đơn có mốc nghiệp vụ trong ngày" (L384), và job cảnh báo 15 phút tồn tại để "bổ sung thông tin kịp trước giờ chốt" (L429). Qua ngày thì hệ thống không tự phát hành lại (L428). Nguồn: QC trả lời 16/10/2026 vòng 1. SC-XHD-096 đổi Then; thêm SC-XHD-111.

Sheet Tổng hợp
A1: TỔNG HỢP CÂU HỎI VÒNG 2 THEO MODULE
A3: Module | B3: Chức năng | C3: Câu còn mở | D3: BLOCKING | E3: Rõ một phần | F3: QC đã rà — chuyển PO | G3: Chưa trả lời | H3: Mới | I3: Đã chốt vòng 1
A4: XHD | B4: Đồng bộ đơn hàng & xuất hóa đơn tự động | C4: =COUNTIF('Câu hỏi vòng 2'!$C$5:$C$53,A4) -> 29 | D4: =COUNTIFS('Câu hỏi vòng 2'!$C$5:$C$53,A4,'Câu hỏi vòng 2'!$F$5:$F$53,"BLOCKING") -> 3 | E4: =COUNTIFS('Câu hỏi vòng 2'!$C$5:$C$53,A4,'Câu hỏi vòng 2'!$H$5:$H$53,"Rõ một phần") -> 6 | F4: =COUNTIFS('Câu hỏi vòng 2'!$C$5:$C$53,A4,'Câu hỏi vòng 2'!$H$5:$H$53,"QC đã rà*") -> 9 | G4: =COUNTIFS('Câu hỏi vòng 2'!$C$5:$C$53,A4,'Câu hỏi vòng 2'!$H$5:$H$53,"Chưa trả lời") -> 12 | H4: =COUNTIFS('Câu hỏi vòng 2'!$C$5:$C$53,A4,'Câu hỏi vòng 2'!$H$5:$H$53,"Mới*") -> 2 | I4: =COUNTIF('Đã chốt vòng 1'!$B$4:$B$7,A4) -> 4
A5: GN | B5: Gạch nợ hóa đơn | C5: =COUNTIF('Câu hỏi vòng 2'!$C$5:$C$53,A5) -> 10 | D5: =COUNTIFS('Câu hỏi vòng 2'!$C$5:$C$53,A5,'Câu hỏi vòng 2'!$F$5:$F$53,"BLOCKING") -> 1 | E5: =COUNTIFS('Câu hỏi vòng 2'!$C$5:$C$53,A5,'Câu hỏi vòng 2'!$H$5:$H$53,"Rõ một phần") -> 0 | F5: =COUNTIFS('Câu hỏi vòng 2'!$C$5:$C$53,A5,'Câu hỏi vòng 2'!$H$5:$H$53,"QC đã rà*") -> 0 | G5: =COUNTIFS('Câu hỏi vòng 2'!$C$5:$C$53,A5,'Câu hỏi vòng 2'!$H$5:$H$53,"Chưa trả lời") -> 9 | H5: =COUNTIFS('Câu hỏi vòng 2'!$C$5:$C$53,A5,'Câu hỏi vòng 2'!$H$5:$H$53,"Mới*") -> 1 | I5: =COUNTIF('Đã chốt vòng 1'!$B$4:$B$7,A5) -> 0
A6: HK | B6: Đẩy hậu kỳ – tiền trả trước | C6: =COUNTIF('Câu hỏi vòng 2'!$C$5:$C$53,A6) -> 10 | D6: =COUNTIFS('Câu hỏi vòng 2'!$C$5:$C$53,A6,'Câu hỏi vòng 2'!$F$5:$F$53,"BLOCKING") -> 2 | E6: =COUNTIFS('Câu hỏi vòng 2'!$C$5:$C$53,A6,'Câu hỏi vòng 2'!$H$5:$H$53,"Rõ một phần") -> 0 | F6: =COUNTIFS('Câu hỏi vòng 2'!$C$5:$C$53,A6,'Câu hỏi vòng 2'!$H$5:$H$53,"QC đã rà*") -> 0 | G6: =COUNTIFS('Câu hỏi vòng 2'!$C$5:$C$53,A6,'Câu hỏi vòng 2'!$H$5:$H$53,"Chưa trả lời") -> 9 | H6: =COUNTIFS('Câu hỏi vòng 2'!$C$5:$C$53,A6,'Câu hỏi vòng 2'!$H$5:$H$53,"Mới*") -> 1 | I6: =COUNTIF('Đã chốt vòng 1'!$B$4:$B$7,A6) -> 0
A7: Tổng | C7: =SUM(C4:C6) -> 49 | D7: =SUM(D4:D6) -> 6 | E7: =SUM(E4:E6) -> 6 | F7: =SUM(F4:F6) -> 9 | G7: =SUM(G4:G6) -> 30 | H7: =SUM(H4:H6) -> 4 | I7: =SUM(I4:I6) -> 4
A9: Câu hỏi BLOCKING:
A10: CL-XHD-21 | B10: BR-XHD-18 "clear thuê thiết bị đầu cuối": có thuộc v2.0? Đặc tả?
A11: CL-XHD-22 | B11: Mail cảnh báo bản tin trễ qua ngày + phương án xử lý: thuộc v2.0? Đặc tả?
A12: CL-XHD-29 | B12: Tài liệu tích hợp: payload Kafka, schema bảng, API, enum
A13: CL-GN-01 | B13: Paid voucher có bị loại khỏi gạch nợ của INVOICE không?
A14: CL-HK-01 | B14: Ký hiệu HĐĐT bản chốt + bảng map; loại HĐ nào dùng đầu M / U / A (kể cả bán thêm)?
A15: CL-HK-03 | B15: Dòng EVC và dòng chiết khấu trên HĐĐT: Out-scope hay có đặc tả?
A17: Ghi chú: "Trả lời vòng 1 (QC)" là câu trả lời của QC owner, không phải xác nhận PO. Câu chỉ được đóng khi chốt được bằng chữ URD 2.2; câu QC báo "không tìm thấy trong tài liệu" chuyển PO trả lời.
